Workbook

Sheet Read Me
B1: 3.3 Prompt Engineering Portfolio: Prompt Evaluation Sheet
B3: Progress (auto) | C3: =COUNT('Evaluation Log'!M2:M34)&" of 33 runs scored" -> 30 of 33 runs scored
B4: What is in this workbook | C4: 11 tasks across Reasoning, Extraction, Summarization and Coding. Each task has v1 (basic), v2 (structured) and v3 (advanced) prompts, the exact prompt text, Gemini's output from your three conversations, scores, and notes on what worked or failed.
B5: How scoring works | C5: Accuracy, Format and Completeness are each scored 1 to 5 against the Answer Key, and Score is their average. Format is judged against the task's target (for example JSON or a table), so a basic prompt that never asked for that format scores lower. That difference is what the portfolio measures. The scores are my assessment of your real outputs, so review them and adjust where you disagree.
B6: Still to do: S1 | C6: S1 (news summary) has no valid result. In your v2 and v3 conversations no article was pasted, and v1 was not run. The S1 prompts here already contain a sample article, so just run all three in new chats and paste the outputs.
B7: Optional extras | C7: Consistency was only tested for E3 v1 (asked twice). If you have time, rerun any v3 prompt twice more and fill the Consistency column. Leave it blank where untested.
B8: Check before submitting | C8: 1) Confirm the model for each run in the Gemini model picker (see the yellow note on the Summary tab). 2) Read the 'Run validity notes' on the Summary tab. 3) Keep the outputs exactly as received.
B9: Colour legend | C9: Dark blue = headers. Grey = prepared. Green = filled from your real runs. Cream = still to fill. Yellow = confirm. Score and the Summary tables are formulas.

Sheet Evaluation Log
A1: Task ID | B1: Category | C1: Task Description | D1: Prompt Version | E1: Status | F1: Model (self-reported) | G1: Technique Used | H1: Prompt Text | I1: Model Output | J1: Accuracy (1-5) | K1: Format (1-5) | L1: Completeness (1-5) | M1: Score (1-5) | N1: Consistency | O1: What Worked / Failed | P1: Next Change
A2: R1 | B2: Reasoning | C2: multi-step word problem | D2: v1 | E2: Run (v1 conversation) | F2: Gemini 3.5 Flash-Lite | G2: Basic (natural ask) | H2: A jacket costs ₹2,000 with a 15% discount, then 5% tax, split among 3 friends. How much does each pay? | I2: Here is the breakdown of the total cost and how much each friend pays: - Original Price: ₹2,000 - After 15% Discount: ₹1,700 (₹2,000 - ₹300) - After 5% Tax: ₹1,785 (₹1,700 + ₹85) - Split among 3 friends: ₹595 each | J2: 5 | K2: 4 | L2: 5 | M2: =IF(COUNT(J2:L2)=3,ROUND(AVERAGE(J2:L2),1),"") -> 4.7 | O2: Correct answer (₹595) in a short, readable breakdown. No numbered calculations and no 'Final answer' line, because the prompt did not ask for them. | P2: Add numbered calculations and a fixed final line (v2).
A3: R1 | B3: Reasoning | C3: multi-step word problem | D3: v2 | E3: Run (v2 conversation) | F3: Gemini 3.8 Flash | G3: Step-by-step + fixed final line | H3: Can you work this out step by step? A jacket costs ₹2,000. It gets a 15% discount first, then 5% tax is added on the discounted price, and 3 friends split the final bill equally. Please show each calculation on its own line and finish with 'Final answer: ₹X per friend'. | I3: I am Gemini, a model trained by Google. [stray line at the top] 1. Discount amount: ₹2,000 × 0.15 = ₹300 2. Discounted price: ₹2,000 − ₹300 = ₹1,700 3. Tax amount (5% on discounted price): ₹1,700 × 0.05 = ₹85 4. Final bill: ₹1,700 + ₹85 = ₹1,785 5. Split per person: ₹1,785 ÷ 3 = ₹595 Final answer: ₹595 per friend | J3: 5 | K3: 5 | L3: 5 | M3: =IF(COUNT(J3:L3)=3,ROUND(AVERAGE(J3:L3),1),"") -> 5 | O3: Followed the format exactly: one calculation per line plus the required final line. Minor: a stray 'I am Gemini' line at the top, probably left over from a model-name question just before. | P3: Add a worked example and a back-check (v3).
A4: R1 | B4: Reasoning | C4: multi-step word problem | D4: v3 | E4: Run (v3 conversation) | F4: Gemini 3.1 Pro | G4: Rules + worked example + back-check | H4: I'm checking my maths homework and the order of operations is what usually trips me up. Please solve the problem below like a careful tutor. Rules: 1. Apply the discount first, then the tax on the discounted price. 2. Don't round until the final answer. 3. Put each calculation on its own numbered line. 4. Afterwards, check your answer by working backwards and write 'Check:' followed by the result. 5. End with 'Final answer: ₹X per friend'. Example of the style I want: Problem: A bag costs ₹1,000 with a 10% discount, then 12% tax, shared by 2 people. 1) 1000 × 0.90 = 900 2) 900 × 1.12 = 1008 3) 1008 ÷ 2 = 504 Check: 504 × 2 = 1008; 1008 ÷ 1.12 = 900; 900 ÷ 0.90 = 1000. Correct. Final answer: ₹504 per person. Now my problem: A jacket costs ₹2,000 with a 15% discount, then 5% tax, split among 3 friends. How much does each pay? | I4: 1. 2000 × 0.85 = 1700 2. 1700 × 1.05 = 1785 3. 1785 ÷ 3 = 595 Check: 595 × 3 = 1785; 1785 ÷ 1.05 = 1700; 1700 ÷ 0.85 = 2000. Correct. Final answer: ₹595 per friend. | J4: 5 | K4: 5 | L4: 5 | M4: =IF(COUNT(J4:L4)=3,ROUND(AVERAGE(J4:L4),1),"") -> 5 | O4: Followed all 5 rules, and the 'Check:' line proves the answer by working backwards. | P4: Full marks on an easy problem, so v2 and v3 barely differ. A harder problem would separate them better.
A5: R2 | B5: Reasoning | C5: logic / scheduling puzzle | D5: v1 | E5: Run (v1 conversation) | F5: Gemini 3.5 Flash-Lite | G5: Basic (natural ask) | H5: Can you solve this puzzle? Four colleagues (Ananya, kiru, Claran and maya) each book one 1-hour slot in a conference room on Monday morning. The slots are 9-10 AM, 10-11 AM, 11 AM-12 PM and 12-1 PM, and everyone gets a different slot. Rules: (1) Clara's meeting is earlier than David's. (2) Ananya's meeting is immediately before Brian's. (3) David cannot have the 12-1 PM slot. (4) Brian is not available 11 AM-12 PM. Who gets which slot? | I5: Here is the step-by-schlution to the puzzle based on the rules provided (noting that the names in the rules correspond to Ananya, Brian, Clara, and David): Slot Assignments: Clara 9-10 AM | David 10-11 AM | Ananya 11 AM-12 PM | Brian 12-1 PM Step-by-Step: (1) Rule 2 gives the pairs 9-10 & 10-11, 10-11 & 11-12, 11-12 & 12-1. (2) Rule 4 removes the 10-11 & 11-12 pair. (3) If Ananya and Brian took 9-10 & 10-11, Clara and David would need 11-12 & 12-1, but David cannot take 12-1, so Ananya and Brian take the later slots. (4) Clara and David take 9-10 and 10-11, Clara first. [condensed; the original contains garbled characters such as '12-1티'] | J5: 5 | K5: 4 | L5: 4 | M5: =IF(COUNT(J5:L5)=3,ROUND(AVERAGE(J5:L5),1),"") -> 4.3 | O5: Final schedule is correct and the reasoning is sound. Weaknesses: a bulleted list instead of a table, garbled characters in the output, and no final check against all four rules. Validity note: my typed prompt used the wrong names (kiru, Claran, maya) while the rules say Clara, David and Brian. Gemini quietly matched them, so this run was not on the exact puzzle text. | P5: Ask for a table and step-by-step reasoning (v2). Retype v1 with the correct names if you rerun it.
A6: R2 | B6: Reasoning | C6: logic / scheduling puzzle | D6: v2 | E6: Run (v2 conversation) | F6: Gemini 3.8 Flash | G6: Step-by-step + table output | H6: I'm stuck on this scheduling puzzle. Please think through it step by step and give the final answer as a table with two columns: Time Slot and Person. Four colleagues (Ananya, Brian, Clara and David) each book one 1-hour slot in a conference room on Monday morning. The slots are 9-10 AM, 10-11 AM, 11 AM-12 PM and 12-1 PM, and everyone gets a different slot. Rules: (1) Clara's meeting is earlier than David's. (2) Ananya's meeting is immediately before Brian's. (3) David cannot have the 12-1 PM slot. (4) Brian is not available 11 AM-12 PM. Who gets which slot? | I6: Tested the placements of Ananya and Brian (Rule 2 and Rule 4): Option A 9-10 / 10-11; Option B 10-11 / 11-12 (invalid, Rule 4); Option C 11-12 / 12-1. Option C leaves 9-10 and 10-11 for Clara and David, so Clara 9-10, David 10-11; Rules 3 and 4 checked and satisfied. Option A forces David into 12-1, which breaks Rule 3, so it is invalid. Table: 9-10 AM Clara | 10-11 AM David | 11 AM-12 PM Ananya | 12-1 PM Brian | J6: 5 | K6: 5 | L6: 5 | M6: =IF(COUNT(J6:L6)=3,ROUND(AVERAGE(J6:L6),1),"") -> 5 | O6: Correct, with the table requested and rules 3 and 4 explicitly checked. | P6: Add a numbered rule list, explicit elimination for every case and a final verification (v3).
A7: R2 | B7: Reasoning | C7: logic / scheduling puzzle | D7: v3 | E7: Run (v3 conversation) | F7: Gemini 3.1 Pro | G7: Method (case elimination) + verification | H7: Act like a logic-puzzle coach. Solve the puzzle below using this method: 1. Number each rule. 2. Find the most restricted person or pair and list all their possible slots. 3. Test every possibility against ALL the rules and write 'eliminated by rule X' or 'valid'. 4. Confirm that exactly one complete schedule survives. 5. Give the final schedule as a table, then a line starting 'Verification:' that checks each rule. Puzzle: Four colleagues (Ananya, Brian, Clara and David) each book one 1-hour slot in a conference room on Monday morning. The slots are 9-10 AM, 10-11 AM, 11 AM-12 PM and 12-1 PM, and everyone gets a different slot. Rules: (1) Clara's meeting is earlier than David's. (2) Ananya's meeting is immediately before Brian's. (3) David cannot have the 12-1 PM slot. (4) Brian is not available 11 AM-12 PM. Who gets which slot? | I7: 1. Rules numbered 1 to 4. 2. Most restricted pair: Ananya and Brian (consecutive slots). Possibilities: (9-10, 10-11), (10-11, 11-12), (11-12, 12-1). 3. Possibility 1: eliminated by rule 3. Possibility 2: eliminated by rule 4. Possibility 3: valid (Clara 9-10, David 10-11 remain). 4. Exactly one schedule survives. 5. Table: 9-10 AM Clara | 10-11 AM David | 11 AM-12 PM Ananya | 12-1 PM Brian Verification: (1) Clara 9-10 is before David 10-11. (2) Ananya 11-12 is immediately before Brian 12-1. (3) David is not at 12-1. (4) Brian is not at 11-12. Correct. | J7: 5 | K7: 5 | L7: 5 | M7: =IF(COUNT(J7:L7)=3,ROUND(AVERAGE(J7:L7),1),"") -> 5 | O7: Followed every step of the method, labelled each elimination with its rule number and ended with a full verification. | P7: Full marks. Keep this method for harder puzzles.
A8: R3 | B8: Reasoning | C8: decision with reasons | D8: v1 | E8: Run (v1 conversation) | F8: Gemini 3.5 Flash-Lite | G8: Basic (natural ask) | H8: Which of these laptops should a student buy, and why? A: ₹48,000 | 8 GB RAM | 512 GB SSD | 1.5 kg | about 9 hours battery B: ₹62,000 | 16 GB RAM | 512 GB SSD | 1.3 kg | about 12 hours battery C: ₹39,000 | 8 GB RAM | 256 GB SSD | 2.2 kg | about 5 hours battery | I8: A student should buy Laptop B (₹62,000): 16 GB RAM is future-proof, 1.3 kg is easy to carry, about 12 hours of battery lasts all day. Laptop A (₹48,000): decent battery and weight but 8 GB RAM may bottleneck; 'a good budget alternative if ₹62,000 strictly exceeds your budget'. Laptop C (₹39,000): cheapest but only 256 GB, 2.2 kg and about 5 hours of battery; not recommended. | J8: 3 | K8: 4 | L8: 4 | M8: =IF(COUNT(J8:L8)=3,ROUND(AVERAGE(J8:L8),1),"") -> 3.7 | O8: Reasonable answer for the information given, with a short hint about budget. But v1 gave no budget, so Gemini picked the best-spec laptop (B), which is the opposite of the right answer once the ₹55,000 limit is known. | P8: Add budget, usage and the criteria to compare (v2). This shows why context matters.
A9: R3 | B9: Reasoning | C9: decision with reasons | D9: v2 | E9: Run (v2 conversation) | F9: Gemini 3.8 Flash | G9: Context (budget, use) + comparison criteria | H9: I'm an engineering student with a budget of ₹55,000. I'll use the laptop for coding and online lectures and carry it to college every day. Which of these three should I buy? Please compare them on price, portability, battery and storage, then give me one clear recommendation. A: ₹48,000 | 8 GB RAM | 512 GB SSD | 1.5 kg | about 9 hours battery B: ₹62,000 | 16 GB RAM | 512 GB SSD | 1.3 kg | about 12 hours battery C: ₹39,000 | 8 GB RAM | 256 GB SSD | 2.2 kg | about 5 hours battery | I9: Comparison table with a 'Fits Budget (≤ ₹55,000)?' column: A yes (₹7,000 to spare), B no (₹7,000 over), C yes. Detailed breakdown by price, portability, battery and storage. Recommendation: Buy Laptop A, the only option that fits the budget while giving 1.5 kg, about 9 hours of battery and 512 GB. | J9: 4 | K9: 5 | L9: 5 | M9: =IF(COUNT(J9:L9)=3,ROUND(AVERAGE(J9:L9),1),"") -> 4.7 | O9: Used the budget, compared on all four criteria and gave one clear recommendation (A). Minor: added assumptions not in the specs (an 'eventual RAM upgrade', Windows system files). | P9: Add a rule-out step, a no-invention rule and 'what would change your answer' (v3).
A10: R3 | B10: Reasoning | C10: decision with reasons | D10: v3 | E10: Run (v3 conversation) | F10: Gemini 3.1 Pro | G10: Hard-constraint rule-out + trade-offs + what-would-change + no-invention rule | H10: Act as an honest tech advisor. My situation: engineering student, coding and online lectures, carry it daily, hard budget limit of ₹55,000. Please: 1. Rule out any laptop that breaks my hard budget limit and say why. 2. Compare the remaining ones in a small table. 3. Explain the trade-offs in plain words. 4. Give ONE recommendation with your reasoning. 5. Tell me what would change your answer (for example, a higher budget). Use only the specs I've listed. Don't invent extra details. A: ₹48,000 | 8 GB RAM | 512 GB SSD | 1.5 kg | about 9 hours battery B: ₹62,000 | 16 GB RAM | 512 GB SSD | 1.3 kg | about 12 hours battery C: ₹39,000 | 8 GB RAM | 256 GB SSD | 2.2 kg | about 5 hours battery | I10: 1. Ruled out Laptop B: ₹62,000 breaks the ₹55,000 hard limit. 2. Table of A vs C (price, RAM, storage, weight, battery). 3. Trade-offs: A costs ₹9,000 more but gives double the storage, a lighter device and nearly double the battery. 4. Recommendation: Laptop A. 5. What would change the answer: a budget above ₹62,000 would make Laptop B the choice (16 GB RAM, lightest, best battery). | J10: 5 | K10: 5 | L10: 5 | M10: =IF(COUNT(J10:L10)=3,ROUND(AVERAGE(J10:L10),1),"") -> 5 | O10: Followed all five steps, used only the listed specs, and gave a useful 'what would change' point. | P10: Full marks.
A11: E1 | B11: Extraction | C11: messy email to JSON | D11: v1 | E11: Run (v1 conversation) | F11: Gemini 3.5 Flash-Lite | G11: Basic (natural ask) | H11: Can you pull out the important details from this email? Subject: invoice question / oct 12th caterign?? Hey Marcus, quick qestion about the bill sent over on Octobr 14th for the event on 10/12. It says the total due is $1,485.50 but i swear we talked about the early bird rate being closer to $1,250? Also noticed a duplicate charge of $75 for ice bags lol. can u look into this before friday so i can run payroll and send the wire out?? thx! - Dave | I11: Here are the important details extracted from the email: - Sender: Dave - Recipient: Marcus - Event Date: October 12th (10/12) - Invoice Date: October 14th - Billed Total: $1,485.50 - Disputed Items / Issues: Rate discrepancy (Dave believes it should be closer to the early bird rate of $1,250); Duplicate charge of $75 for ice bags - Deadline: Before Friday (so payroll and the wire transfer can be processed) | J11: 5 | K11: 3 | L11: 5 | M11: =IF(COUNT(J11:L11)=3,ROUND(AVERAGE(J11:L11),1),"") -> 4.3 | O11: All values are correct and nothing was invented. Format is a clear bulleted list, not JSON, because v1 never asked for JSON. | P11: Name the JSON keys (v2).
A12: E1 | B12: Extraction | C12: messy email to JSON | D12: v2 | E12: Run (v2 conversation) | F12: Gemini 3.8 Flash | G12: JSON key list | H12: Please extract the details from this email and return them as JSON with these keys: sender_name, recipient_name, bill_date, event_date, total_due_usd, expected_rate_usd, duplicate_charge_usd, response_deadline. Email: Subject: invoice question / oct 12th caterign?? Hey Marcus, quick qestion about the bill sent over on Octobr 14th for the event on 10/12. It says the total due is $1,485.50 but i swear we talked about the early bird rate being closer to $1,250? Also noticed a duplicate charge of $75 for ice bags lol. can u look into this before friday so i can run payroll and send the wire out?? thx! - Dave | I12: { "sender_name": "Dave", "recipient_name": "Marcus", "bill_date": "October 14th", "event_date": "10/12", "total_due_usd": 1485.50, "expected_rate_usd": 1250.00, "duplicate_charge_usd": 75.00, "response_deadline": "Friday" } | J12: 5 | K12: 4 | L12: 5 | M12: =IF(COUNT(J12:L12)=3,ROUND(AVERAGE(J12:L12),1),"") -> 4.7 | O12: Valid JSON with the right keys and correct numbers; no invented year. Minor: dates use mixed formats ('October 14th' vs '10/12'). | P12: Add a date-format rule, a null rule and an example (v3).
A13: E1 | B13: Extraction | C13: messy email to JSON | D13: v3 | E13: Run (v3 conversation) | F13: Gemini 3.1 Pro | G13: Rules + example + null for missing values | H13: You are a careful data-entry assistant. Read the email and return ONLY valid JSON (no explanation, no markdown) with exactly these keys: sender_name, recipient_name, bill_date, event_date, total_due_usd, expected_rate_usd, duplicate_charge_usd, response_deadline. Rules: - Write dates as MM-DD. The year isn't given, so don't guess it. - Money values are plain numbers (no $ or commas). - If something isn't in the email, use null. Never make up a value. - Copy the deadline as written (for example, 'Friday'). Example email: "hi sam, quick one: the bill from may 3rd for the workshop on 5/1 shows $900 but we agreed on about $800. pls fix by monday. - priya" Example output: {"sender_name":"Priya","recipient_name":"Sam","bill_date":"05-03","event_date":"05-01","total_due_usd":900,"expected_rate_usd":800,"duplicate_charge_usd":null,"response_deadline":"Monday"} Email: Subject: invoice question / oct 12th caterign?? Hey Marcus, quick qestion about the bill sent over on Octobr 14th for the event on 10/12. It says the total due is $1,485.50 but i swear we talked about the early bird rate being closer to $1,250? Also noticed a duplicate charge of $75 for ice bags lol. can u look into this before friday so i can run payroll and send the wire out?? thx! - Dave | I13: { "sender_name": "Dave", "recipient_name": "Marcus", "bill_date": "10-14", "event_date": "10-12", "total_due_usd": 1485.5, "expected_rate_usd": 1250, "duplicate_charge_usd": 75, "response_deadline": "friday" } | J13: 5 | K13: 5 | L13: 5 | M13: =IF(COUNT(J13:L13)=3,ROUND(AVERAGE(J13:L13),1),"") -> 5 | O13: Every value matches the key. Dates are in the requested MM-DD format, money is plain numbers, and the deadline is copied as written ('friday'). | P13: Full marks.
... A16: E2 | B16: Extraction | C16: action items from meeting notes | D16: v3 | E16: Run (v3 conversation) | F16: Gemini 3.1 Pro | G16: Rules for Unassigned / Not set + count line + example row | H16: You are a project assistant. List only the tasks someone has to DO, not general discussion. Rules: - Return a markdown table with columns: Action | Owner | Deadline. - If nobody is clearly assigned, write 'Unassigned'. Don't assume the person who mentioned it owns it. - If there's no date, write 'Not set'. - After the table, write 'Total action items: N'. Example row: | Book the meeting room | Anil | Monday | Notes: Project Falcon weekly sync, 28 Sept. Present: Meera, Karthik, Sana, Dev. - Meera said she will send the revised budget to finance by Friday. - We agreed the logo needs another round. Karthik to share 3 new options by Wed. - Sana mentioned the vendor contract is still unsigned, someone should chase it. - Dev will fix the login bug, no date yet. - General chat about the offsite, nothing decided. | I16: Table: Send the revised budget to finance | Meera | Friday; Share 3 new logo options | Karthik | Wed; Chase unsigned vendor contract | Unassigned | Not set; Fix the login bug | Dev | Not set Total action items: 4 | J16: 5 | K16: 5 | L16: 5 | M16: =IF(COUNT(J16:L16)=3,ROUND(AVERAGE(J16:L16),1),"") -> 5 | O16: Exact placeholders ('Unassigned', 'Not set'), correct owners and the count line. | P16: Full marks.
A17: E3 | B17: Extraction | C17: product details with missing information | D17: v1 | E17: Run (v1 conversation) | F17: Gemini 3.5 Flash-Lite | G17: Basic (natural ask) | H17: What details can you tell me about the product in this review? Picked up the Zephyr X2 earbuds last month for about ₹2,500. The battery easily lasts a full day and the bass is punchy. The charging case feels a bit cheap though. I haven't tried them in the rain, so no idea about water resistance. | I17: (Run 1) Based on the review, here are the key details about the Zephyr X2 earbuds: - Price: Around ₹2,500 (purchased last month) - Battery Life: Easily lasts a full day on a single charge - Sound Quality: Features punchy bass - Build & Design: The earbuds/sound are well-received, but the charging case feels a bit cheap - Water Resistance: Untested in the rain, so unknown (Run 2, same prompt) Same list, but Build Quality: 'The charging case feels a bit cheap' only. | J17: 4 | K17: 3 | L17: 4 | M17: =IF(COUNT(J17:L17)=3,ROUND(AVERAGE(J17:L17),1),"") -> 3.7 | N17: Medium | O17: Did not invent water resistance. Weaknesses: bulleted list instead of JSON; run 1 added an unsupported claim ('earbuds/sound are well-received') that run 2 dropped, so the same prompt gave slightly different quality. It also never says noise cancellation and colour are missing. | P17: Name the JSON keys and require null for missing details (v2).
A18: E3 | B18: Extraction | C18: product details with missing information | D18: v2 | E18: Run (v2 conversation) | F18: Gemini 3.8 Flash | G18: JSON key list | H18: Extract the product details from this review into JSON with the keys: product_name, price_inr, battery, sound_quality, build_quality, water_resistance, noise_cancellation, colour. Review: Picked up the Zephyr X2 earbuds last month for about ₹2,500. The battery easily lasts a full day and the bass is punchy. The charging case feels a bit cheap though. I haven't tried them in the rain, so no idea about water resistance. | I18: { "product_name": "Zephyr X2 earbuds", "price_inr": 2500, "battery": "easily lasts a full day", "sound_quality": "punchy bass", "build_quality": "charging case feels a bit cheap", "water_resistance": null, "noise_cancellation": null, "colour": null } | J18: 5 | K18: 5 | L18: 5 | M18: =IF(COUNT(J18:L18)=3,ROUND(AVERAGE(J18:L18),1),"") -> 5 | O18: Correct JSON, with null for every missing detail and nothing invented. | P18: Add the approximate-price flag and a never-guess rule (v3).
A19: E3 | B19: Extraction | C19: product details with missing information | D19: v3 | E19: Run (v3 conversation) | F19: Gemini 3.1 Pro | G19: Never-guess rule + approximate-price flag | H19: You are a careful product-data analyst. Extract details from the review below as ONLY valid JSON with these keys: product_name, price_inr, battery, sound_quality, build_quality, water_resistance, noise_cancellation, colour. Rules: - Use only what the reviewer actually says. If a detail isn't mentioned, or the reviewer says they don't know, use null. - Never guess or fill in typical specs for this kind of product. - price_inr is a number. The reviewer says 'about', so add a key price_is_approximate set to true or false. - Keep the other values to a short phrase in the reviewer's words. Review: Picked up the Zephyr X2 earbuds last month for about ₹2,500. The battery easily lasts a full day and the bass is punchy. The charging case feels a bit cheap though. I haven't tried them in the rain, so no idea about water resistance. | I19: { "product_name": "Zephyr X2 earbuds", "price_inr": 2500, "battery": "easily lasts a full day", "sound_quality": "bass is punchy", "build_quality": "charging case feels a bit cheap", "water_resistance": null, "noise_cancellation": null, "colour": null, "price_is_approximate": true } | J19: 5 | K19: 5 | L19: 5 | M19: =IF(COUNT(J19:L19)=3,ROUND(AVERAGE(J19:L19),1),"") -> 5 | O19: Correct, and the extra price_is_approximate flag handled the word 'about'. | P19: Full marks.
A20: S1 | B20: Summarization | C20: news article into 3 bullets | D20: v1 | E20: To run (rerun) | G20: Basic (natural ask) | H20: Can you summarize this article for me? Rivertown to launch 40 electric buses on three city routes from 1 November Rivertown Municipal Transport will put 40 electric buses on the road on 1 November, covering three routes that link the railway station, the main market and the university campus. The buses were bought with a Rs 96 crore grant from the state government and will replace 55 diesel buses that are more than 12 years old. Officials say the flat fare will stay at Rs 15 for the first six months. Each bus can run about 180 kilometres on a single charge, and two new charging depots at Eastside and Lakeview will handle overnight charging. The transport department estimates that the switch will cut the city's bus emissions by about 30 percent and save Rs 8 crore a year in fuel costs. Not everyone is convinced. A commuters' association said the 40 new buses are fewer than the 55 being retired, and it fears longer waiting times during peak hours. The department replied that a further 25 buses will be ordered next year if passenger numbers hold up. The first buses will be flagged off by the mayor at the railway station at 8 a.m. | M20: =IF(COUNT(J20:L20)=3,ROUND(AVERAGE(J20:L20),1),"") | O20: Not run before. This prompt now includes a sample article, ready to run.
A21: S1 | B21: Summarization | C21: news article into 3 bullets | D21: v2 | E21: To run (rerun) | G21: Length + audience constraint | H21: Please summarize this article in exactly 3 bullet points, each under 20 words, for a general reader. Rivertown to launch 40 electric buses on three city routes from 1 November Rivertown Municipal Transport will put 40 electric buses on the road on 1 November, covering three routes that link the railway station, the main market and the university campus. The buses were bought with a Rs 96 crore grant from the state government and will replace 55 diesel buses that are more than 12 years old. Officials say the flat fare will stay at Rs 15 for the first six months. Each bus can run about 180 kilometres on a single charge, and two new charging depots at Eastside and Lakeview will handle overnight charging. The transport department estimates that the switch will cut the city's bus emissions by about 30 percent and save Rs 8 crore a year in fuel costs. Not everyone is convinced. A commuters' association said the 40 new buses are fewer than the 55 being retired, and it fears longer waiting times during peak hours. The department replied that a further 25 buses will be ordered next year if passenger numbers hold up. The first buses will be flagged off by the mayor at the railway station at 8 a.m. | M21: =IF(COUNT(J21:L21)=3,ROUND(AVERAGE(J21:L21),1),"") | O21: Earlier attempt not scored: in your transcript no article was pasted (v2 and v3), so Gemini asked for it; v1 was never run. This prompt now includes a sample article, ready to run.
A22: S1 | B22: Summarization | C22: news article into 3 bullets | D22: v3 | E22: To run (rerun) | G22: Bullet roles + no-outside-facts rule + format example | H22: You are a news editor. Summarize the article below in exactly 3 bullet points. Rules: - Bullet 1: what happened. Bullet 2: the most important detail or quote. Bullet 3: what happens next. - Each bullet is 20 words or fewer. - Use only facts stated in the article. Don't add outside knowledge or opinions. - Output only the 3 bullets. Format example: - Company X will open 5 stores on 1 May, replacing 3 older ones. Article: Rivertown to launch 40 electric buses on three city routes from 1 November Rivertown Municipal Transport will put 40 electric buses on the road on 1 November, covering three routes that link the railway station, the main market and the university campus. The buses were bought with a Rs 96 crore grant from the state government and will replace 55 diesel buses that are more than 12 years old. Officials say the flat fare will stay at Rs 15 for the first six months. Each bus can run about 180 kilometres on a single charge, and two new charging depots at Eastside and Lakeview will handle overnight charging. The transport department estimates that the switch will cut the city's bus emissions by about 30 percent and save Rs 8 crore a year in fuel costs. Not everyone is convinced. A commuters' association said the 40 new buses are fewer than the 55 being retired, and it fears longer waiting times during peak hours. The department replied that a further 25 buses will be ordered next year if passenger numbers hold up. The first buses will be flagged off by the mayor at the railway station at 8 a.m. | M22: =IF(COUNT(J22:L22)=3,ROUND(AVERAGE(J22:L22),1),"") | O22: Earlier attempt not scored: in your transcript no article was pasted (v2 and v3), so Gemini asked for it; v1 was never run. This prompt now includes a sample article, ready to run.
A23: S2 | B23: Summarization | C23: abstract for a 10-year-old | D23: v1 | E23: Run (v1 conversation) | F23: Gemini 3.5 Flash-Lite | G23: Basic (natural ask) | H23: Can you explain this research abstract in simple words? Background: Adolescents often sleep fewer hours than recommended, yet the effect of short sleep on learning is not well quantified. Methods: We conducted a randomized crossover study with 84 students aged 14 to 16. Each participant slept either 6 or 9 hours per night for five consecutive nights, then completed a standardized vocabulary-learning task and a delayed recall test 24 hours later. Results: Students recalled 22% fewer words after the 6-hour condition than after the 9-hour condition (p < 0.001). Reaction times were also 11% slower. Effects were similar across sexes. Conclusions: Even modest sleep restriction measurably impairs memory consolidation in teenagers. School start times and sleep education may deserve greater attention. | I23: Here is a simple breakdown of what this study means: - What they tested: how getting less sleep affects how well teenagers learn and remember. - How they did it: 84 teenagers (14 to 16) slept 6 or 9 hours a night for five days, then tried to learn vocabulary. - What they found: after 6 hours they remembered 22% fewer words a day later, and their reaction times were 11% slower. - The takeaway: even a little sleep loss hurts a teenager's ability to remember and process information; schools and parents should help teens get enough sleep. [condensed, about 140 words in the original] | J23: 5 | K23: 2 | L23: 5 | M23: =IF(COUNT(J23:L23)=3,ROUND(AVERAGE(J23:L23),1),"") -> 4 | O23: Accurate and keeps the key numbers (22%, 11%). But it is about 140 words in bullets, not a short paragraph of about 50 words for a 10-year-old. | P23: State the audience and the length (v2).
A24: S2 | B24: Summarization | C24: abstract for a 10-year-old | D24: v2 | E24: Run (v2 conversation) | F24: Gemini 3.8 Flash | G24: Audience + length target | H24: Please rewrite this abstract in about 50 words so a 10-year-old can understand it. Use short sentences and everyday words. Background: Adolescents often sleep fewer hours than recommended, yet the effect of short sleep on learning is not well quantified. Methods: We conducted a randomized crossover study with 84 students aged 14 to 16. Each participant slept either 6 or 9 hours per night for five consecutive nights, then completed a standardized vocabulary-learning task and a delayed recall test 24 hours later. Results: Students recalled 22% fewer words after the 6-hour condition than after the 9-hour condition (p < 0.001). Reaction times were also 11% slower. Effects were similar across sexes. Conclusions: Even modest sleep restriction measurably impairs memory consolidation in teenagers. School start times and sleep education may deserve greater attention. | I24: Scientists tested 84 teenagers to see how sleep affects their brains. For five nights, the kids slept either six or nine hours. The students who slept less forgot more new words and were slower to react. This proves that getting enough sleep every night helps your brain learn and remember things. | J24: 4 | K24: 5 | L24: 3 | M24: =IF(COUNT(J24:L24)=3,ROUND(AVERAGE(J24:L24),1),"") -> 4 | O24: 51 words (counted), short sentences and everyday words. But it dropped the key number (22%) and 'This proves' overstates what one study shows. | P24: Add a word range, banned jargon, the key number and a self word count (v3).
A25: S2 | B25: Summarization | C25: abstract for a 10-year-old | D25: v3 | E25: Run (v3 conversation) | F25: Gemini 3.1 Pro | G25: Strict word range + banned jargon + key number + self word count | H25: Rewrite the abstract below for a curious 10-year-old. Rules: - 45 to 55 words. - Short, friendly sentences and everyday words. Avoid: randomized, crossover, consolidation, p-value. - Include the main result with its key number, and say why it matters. - Don't add anything that isn't in the abstract. - After the paragraph, write 'Word count: N' (count carefully). Abstract: Background: Adolescents often sleep fewer hours than recommended, yet the effect of short sleep on learning is not well quantified. Methods: We conducted a randomized crossover study with 84 students aged 14 to 16. Each participant slept either 6 or 9 hours per night for five consecutive nights, then completed a standardized vocabulary-learning task and a delayed recall test 24 hours later. Results: Students recalled 22% fewer words after the 6-hour condition than after the 9-hour condition (p < 0.001). Reaction times were also 11% slower. Effects were similar across sexes. Conclusions: Even modest sleep restriction measurably impairs memory consolidation in teenagers. School start times and sleep education may deserve greater attention. | I25: Scientists tested teenagers who slept six hours a night instead of nine. The tired teens remembered 22% fewer new words! They also reacted slower. This proves that losing a little sleep really hurts your memory. It shows why school start times and learning about sleep deserve much more attention. Word count: 49 | J25: 4 | K25: 5 | L25: 5 | M25: =IF(COUNT(J25:L25)=3,ROUND(AVERAGE(J25:L25),1),"") -> 4.7 | O25: 49 words (counted; Gemini's own count is right), no jargon, includes 22% and why it matters. Still says 'This proves', which overclaims. | P25: Add a rule against words like 'proves' and use 'suggests' instead.
A26: C1 | B26: Coding | C26: email validator function | D26: v1 | E26: Run (v1 conversation) | F26: Gemini 3.5 Flash-Lite | G26: Basic (natural ask) | H26: Can you write a Python function that checks whether an email address is valid? | I26: import re def is_valid_email(email: str) -> bool: pattern = r"^[a-zA-Z0-9_.+-]+@[a-zA-Z0-9-]+\.[a-zA-Z0-9-.]+$" if re.match(pattern, email): return True return False # examples + short 'How it works' bullets + note that real verification needs a confirmation link | J26: 4 | K26: 4 | L26: 3 | M26: =IF(COUNT(J26:L26)=3,ROUND(AVERAGE(J26:L26),1),"") -> 3.7 | O26: I ran the 10 tests: 9/10 pass. It wrongly accepts 'john@example..com' (consecutive dots), and a non-string input crashes with TypeError. | P26: Specify the function name, docstring and standard library (v2).
A27: C1 | B27: Coding | C27: email validator function | D27: v2 | E27: Run (v2 conversation) | F27: Gemini 3.8 Flash | G27: Signature + docstring + standard library only | H27: I'm learning Python. Please write a function is_valid_email(email: str) -> bool that checks whether an email address is valid. Use only the standard library, add a docstring, and explain in two sentences how it works. | I27: import re def is_valid_email(email: str) -> bool: """Validate whether an input string conforms to standard email syntax. [Args / Returns docstring]""" pattern = r"^[a-zA-Z0-9_.+-]+@[a-zA-Z0-9-]+\.[a-zA-Z0-9-.]+$" return bool(re.match(pattern, email)) + two-sentence explanation | J27: 4 | K27: 5 | L27: 3 | M27: =IF(COUNT(J27:L27)=3,ROUND(AVERAGE(J27:L27),1),"") -> 4 | O27: Followed the requested format (docstring, standard library, two sentences). But it is the same regex as v1: 9/10 tests, and non-string input still crashes. Better wording did not fix the logic. | P27: Spell out the edge-case rules and give asserts (v3).
A28: C1 | B28: Coding | C28: email validator function | D28: v3 | E28: Run (v3 conversation) | F28: Gemini 3.1 Pro | G28: Explicit edge-case rules + built-in asserts | H28: You are a senior Python developer. Write is_valid_email(email: str) -> bool using the re module. Rules: - Exactly one '@' and no spaces. - The part before '@' is not empty and may contain letters, digits and . _ % + - - The domain has at least one dot. Every part between dots is non-empty and uses letters, digits or hyphens. No consecutive dots and no leading dot. - The last part (like 'com') has at least 2 letters. - Non-string input returns False. Include a docstring, then these 10 assert statements: Valid: john.doe@example.com, a_b+tag@mail.co.in, user123@sub.domain.org Invalid: john@, @example.com, john@example, 'john doe@example.com', john@@example.com, john@example..com, john@.com Reply with one code block and one line saying how many asserts you expect to pass. | I28: import re def is_valid_email(email: str) -> bool: """[docstring listing the rules]""" if not isinstance(email, str): return False pattern = r"^[a-zA-Z0-9._%+-]+@[a-zA-Z0-9-]+(\.[a-zA-Z0-9-]+)*\.[a-zA-Z]{2,}$" return bool(re.match(pattern, email)) [10 assert statements] I expect all 10 asserts to pass. | J28: 5 | K28: 5 | L28: 5 | M28: =IF(COUNT(J28:L28)=3,ROUND(AVERAGE(J28:L28),1),"") -> 5 | O28: I ran it: 10/10 pass, and non-string input returns False. Its prediction ('all 10 pass') was correct. Tiny edge case: a trailing newline ('a@b.com\n') is still accepted. | P28: Full marks. Listing explicit rules plus test cases fixed the consecutive-dot bug.
A29: C2 | B29: Coding | C29: debug a hidden bug | D29: v1 | E29: Run (v1 conversation) | F29: Gemini 3.5 Flash-Lite | G29: Basic (natural ask) | H29: This Python function gives me the wrong answer. Can you find the bug and fix it? def average_marks(marks): total = 0 for i in range(len(marks) - 1): total += marks[i] return total / len(marks) | I29: Here are the bugs in your original function: 1. Missing the last element: range(len(marks) - 1) stops one item short. 2. Wrong loop boundary: it should iterate over all elements, or use sum(). 3. Indentation/Syntax issue: 'return total / len(marks)' was placed on a new line or misaligned. Fixed code: def average_marks(marks): if not marks: return 0; return sum(marks) / len(marks) | J29: 4 | K29: 3 | L29: 5 | M29: =IF(COUNT(J29:L29)=3,ROUND(AVERAGE(J29:L29),1),"") -> 4 | O29: Found the real bug and gave a correct fix, plus an empty-list guard. But bugs 1 and 2 are the same issue, and bug 3 comes from a line break in my pasted code ('return' then a new line), so the answer is padded and a little confusing. Returning 0 for an empty list is a design choice, not the only option. | P29: Give the intended behaviour and ask for a two-sentence explanation (v2).
A30: C2 | B30: Coding | C30: debug a hidden bug | D30: v2 | E30: Run (v2 conversation) | F30: Gemini 3.8 Flash | G30: Intended behaviour + two-sentence explanation | H30: This function should return the average of a list of marks, so average_marks([80, 90, 100]) should give 90, but it doesn't. Please find the bug, explain it in two sentences, and show the corrected code. def average_marks(marks): total = 0 for i in range(len(marks) - 1): total += marks[i] return total / len(marks) | I30: The bug is in range(len(marks) - 1), which stops one element too early and completely excludes the last mark from the sum. Because range(n) is already exclusive of the upper bound, subtracting 1 iterates over indices 0 to n - 2 instead of 0 to n - 1. Corrected code: [loop over range(len(marks)) with an empty-list guard] (Pythonic alternative: sum(marks) / len(marks)). | J30: 5 | K30: 5 | L30: 5 | M30: =IF(COUNT(J30:L30)=3,ROUND(AVERAGE(J30:L30),1),"") -> 5 | O30: Exactly two sentences, correct cause, correct fix and a bonus empty-list guard. | P30: Ask Gemini to trace the code and list other risks (v3).
A31: C2 | B31: Coding | C31: debug a hidden bug | D31: v3 | E31: Run (v3 conversation) | F31: Gemini 3.1 Pro | G31: Trace, Bug, Fix, Risks sections | H31: You are a Python debugging assistant. This function should return the average of a list of marks; average_marks([80, 90, 100]) should return 90, but it doesn't. Please answer in exactly these sections: 1) Trace: run the function by hand on [80, 90, 100], showing each loop step and the returned value versus the expected value. 2) Bug: the exact line that is wrong and why. 3) Fix: the smallest corrected version of the code. 4) Other risks: any other edge cases (for example an empty list), without changing the fix. def average_marks(marks): total = 0 for i in range(len(marks) - 1): total += marks[i] return total / len(marks) | I31: 1) Trace: marks = [80, 90, 100]; range(2) gives i = 0 and 1; total becomes 80, then 170; the last item (100) is skipped; returns 170 / 3 = 56.666..., expected 90.0. 2) Bug: for i in range(len(marks) - 1) stops one index short. 3) Fix: for mark in marks: total += mark; return total / len(marks) 4) Other risks: an empty list raises ZeroDivisionError. | J31: 5 | K31: 5 | L31: 5 | M31: =IF(COUNT(J31:L31)=3,ROUND(AVERAGE(J31:L31),1),"") -> 5 | O31: Followed all four sections. The trace proves the bug (56.67 vs 90) and the empty-list risk is noted without changing the fix. | P31: Full marks.
A32: C3 | B32: Coding | C32: explain code line by line | D32: v1 | E32: Run (v1 conversation) | F32: Gemini 3.5 Flash-Lite | G32: Basic (natural ask) | H32: Can you explain what this code does? def unique(items): seen = set() out = [] for x in items: if x not in seen: seen.add(x) out.append(x) return out | I32: This Python function takes a list (or any iterable) and removes duplicates while preserving the original order. How it works: (1) seen = set() tracks items already met (very fast O(1) lookups); (2) out = [] stores unique items in first-seen order; (3) loop over items; (4) if x not in seen, add to seen and append to out; (5) return out. Example: unique([1, 2, 2, 3, 1, 4, 2]) returns [1, 2, 3, 4]. | J32: 5 | K32: 4 | L32: 4 | M32: =IF(COUNT(J32:L32)=3,ROUND(AVERAGE(J32:L32),1),"") -> 4.3 | O32: Correct explanation with a correct example output. No step-by-step trace, and no explanation of why a set is better than a list. | P32: Ask for a line-by-line explanation for a beginner (v2).
A33: C3 | B33: Coding | C33: explain code line by line | D33: v2 | E33: Run (v2 conversation) | F33: Gemini 3.8 Flash | G33: Beginner audience + line-by-line + one sentence | H33: I'm a beginner in Python. Please explain this function line by line, then tell me in one sentence what the whole function does. def unique(items): seen = set() out = [] for x in items: if x not in seen: seen.add(x) out.append(x) return out | I33: Line-by-line explanation of all 8 lines (def, seen = set(), out = [], for, if x not in seen, seen.add, out.append, return), then: 'This function removes duplicate elements from a sequence while preserving the original order of their first appearance.' | J33: 5 | K33: 5 | L33: 4 | M33: =IF(COUNT(J33:L33)=3,ROUND(AVERAGE(J33:L33),1),"") -> 4.7 | O33: Clear and correct line-by-line explanation with the one-sentence summary requested. It mentions fast set lookups but gives no worked example. | P33: Add a worked trace, the 'why a set' question and a speed note (v3).
A34: C3 | B34: Coding | C34: explain code line by line | D34: v3 | E34: Run (v3 conversation) | F34: Gemini 3.1 Pro | G34: Mentor role + ordered 5-part answer + worked trace | H34: Act as a patient Python mentor. Explain the function below in this order: 1. One sentence on what it does overall. 2. A line-by-line explanation in plain words. 3. Walk through the input [3, 1, 3, 2, 1] and show what 'seen' and 'out' contain after each loop step. 4. Why a set is used for 'seen' instead of a list. 5. One sentence on how fast it is for long lists. Explain any technical term the first time you use it. def unique(items): seen = set() out = [] for x in items: if x not in seen: seen.add(x) out.append(x) return out | I34: 1. Overall: returns only the unique items, in the order they first appeared. 2. Line-by-line explanation, defining each term (function, set, list, loop) on first use. 3. Walkthrough of [3, 1, 3, 2, 1]: seen = {3}, out = [3]; then {1, 3}, [3, 1]; 3 skipped; {1, 2, 3}, [3, 1, 2]; 1 skipped. 4. A set is used because it finds items instantly through hashing, while a list must be scanned one item at a time. 5. Runs in linear time, so it stays fast on very long lists. | J34: 5 | K34: 5 | L34: 5 | M34: =IF(COUNT(J34:L34)=3,ROUND(AVERAGE(J34:L34),1),"") -> 5 | O34: Followed the 5-part order, the trace is correct at every step, and technical terms are explained when first used. | P34: Full marks.

Sheet Task Inputs & Answer Key
A1: Task ID | B1: Category | C1: Task | D1: Input | E1: Correct Answer / What to check | F1: Source / Note
A2: R1 | B2: Reasoning | C2: multi-step word problem | D2: A jacket costs ₹2,000 with a 15% discount, then 5% tax, split among 3 friends. How much does each pay? | E2: ₹595 (2000 × 0.85 = 1700; × 1.05 = 1785; ÷ 3 = 595). | F2: Written for this exercise.
A3: R2 | B3: Reasoning | C3: logic / scheduling puzzle | D3: Four colleagues (Ananya, Brian, Clara and David) each book one 1-hour slot in a conference room on Monday morning. The slots are 9-10 AM, 10-11 AM, 11 AM-12 PM and 12-1 PM, and everyone gets a different slot. Rules: (1) Clara's meeting is earlier than David's. (2) Ananya's meeting is immediately before Brian's. (3) David cannot have the 12-1 PM slot. (4) Brian is not available 11 AM-12 PM. Who gets which slot? | E3: 9-10 Clara, 10-11 David, 11-12 Ananya, 12-1 Brian (the only valid schedule). | F3: Written for this exercise.
A4: R3 | B4: Reasoning | C4: decision with reasons | D4: A: ₹48,000 | 8 GB RAM | 512 GB SSD | 1.5 kg | about 9 hours battery B: ₹62,000 | 16 GB RAM | 512 GB SSD | 1.3 kg | about 12 hours battery C: ₹39,000 | 8 GB RAM | 256 GB SSD | 2.2 kg | about 5 hours battery (v2 and v3 add: engineering student, coding and online lectures, carries it daily, budget ₹55,000. v1 gives no context.) | E4: With the ₹55,000 budget: B is ruled out; A beats C (more storage, lighter, longer battery for ₹9,000 more). Without a budget, B is a defensible pick, which is why v1 chose it. | F4: Written for this exercise.
A5: E1 | B5: Extraction | C5: messy email to JSON | D5: Email from Dave to Marcus about a catering invoice (see the E1 prompts in the Evaluation Log for the full text). | E5: sender Dave, recipient Marcus, bill_date 10-14, event_date 10-12, total_due_usd 1485.50, expected_rate_usd 1250, duplicate_charge_usd 75, response_deadline 'friday'. No invented year. | F5: Written for this exercise.
A6: E2 | B6: Extraction | C6: action items from meeting notes | D6: Project Falcon weekly sync notes with 5 bullets (see the E2 prompts in the Evaluation Log for the full text). | E6: 4 items: Meera (budget, Friday), Karthik (3 logo options, Wednesday), vendor contract (Unassigned, no date), Dev (login bug, no date). Offsite chat is not an action item. | F6: Written for this exercise.
A7: E3 | B7: Extraction | C7: product details with missing information | D7: Review of the Zephyr X2 earbuds (see the E3 prompts in the Evaluation Log for the full text). | E7: product Zephyr X2 earbuds, price 2500 (approximate), battery full day, bass punchy, case feels cheap; water_resistance, noise_cancellation and colour are null. | F7: Written for this exercise.
A8: S1 | B8: Summarization | C8: news article into 3 bullets | D8: Rivertown to launch 40 electric buses on three city routes from 1 November Rivertown Municipal Transport will put 40 electric buses on the road on 1 November, covering three routes that link the railway station, the main market and the university campus. The buses were bought with a Rs 96 crore grant from the state government and will replace 55 diesel buses that are more than 12 years old. Officials say the flat fare will stay at Rs 15 for the first six months. Each bus can run about 180 kilometres on a single charge, and two new charging depots at Eastside and Lakeview will handle overnight charging. The transport department estimates that the switch will cut the city's bus emissions by about 30 percent and save Rs 8 crore a year in fuel costs. Not everyone is convinced. A commuters' association said the 40 new buses are fewer than the 55 being retired, and it fears longer waiting times during peak hours. The department replied that a further 25 buses will be ordered next year if passenger numbers hold up. The first buses will be flagged off by the mayor at the railway station at 8 a.m. | E8: Exactly 3 bullets of 20 words or fewer: (1) 40 electric buses on 3 routes from 1 November, replacing 55 old diesel buses; (2) about 30% lower emissions and Rs 8 crore yearly fuel savings; (3) commuters fear longer waits because 40 is fewer than 55; 25 more buses may follow. No outside facts. | F8: Sample article written for this exercise (fictional), because the Chandrayaan article in your first transcript could not be verified. You may swap in a real article, but then rewrite this key.
A9: S2 | B9: Summarization | C9: abstract for a 10-year-old | D9: Sample abstract on teenage sleep and memory (see the S2 prompts in the Evaluation Log for the full text). | E9: 45 to 55 words, no jargon, and says teens who slept 6 hours remembered about a fifth (22%) fewer words than after 9 hours. | F9: Sample abstract written for this exercise, not a real paper.
A10: C1 | B10: Coding | C10: email validator function | D10: (No input text. The prompt itself is the task.) | E10: Run the 10 tests: valid john.doe@example.com, a_b+tag@mail.co.in, user123@sub.domain.org; invalid john@, @example.com, john@example, 'john doe@example.com', john@@example.com, john@example..com, john@.com. Score accuracy by tests passed (10=5, 9=4, 7-8=3). | F10: Written for this exercise.
A11: C2 | B11: Coding | C11: debug a hidden bug | D11: def average_marks(marks): total = 0 for i in range(len(marks) - 1): total += marks[i] return total / len(marks) | E11: Bug: range(len(marks) - 1) skips the last item. Returns 170/3 = 56.67 instead of 90. Fix: loop over the items or use sum(marks)/len(marks). Empty-list crash is a bonus. | F11: Written for this exercise.
A12: C3 | B12: Coding | C12: explain code line by line | D12: def unique(items): seen = set() out = [] for x in items: if x not in seen: seen.add(x) out.append(x) return out | E12: Removes duplicates and keeps first-seen order; unique([3, 1, 3, 2, 1]) returns [3, 1, 2]; a set makes the 'seen?' check fast; one pass through the list. | F12: Written for this exercise.

Sheet Scoring Rubric
A1: Score | B1: Meaning
A2: 5 | B2: Fully correct, follows the target format, nothing missing
A3: 4 | B3: Correct with a minor flaw
A4: 3 | B4: Partly correct or missing something
A5: 2 | B5: Mostly wrong or ignores the target format
A6: 1 | B6: Unusable
A8: Criterion | B8: How to judge it
A9: Accuracy | B9: Correct versus the Answer Key (facts, numbers, logic; code that runs and passes the tests).
A10: Format | B10: Matches the task's target structure (JSON, table, 3 bullets, word limit, code block). Scored against the target, not only against what the prompt asked.
A11: Completeness | B11: Nothing required is missing; nothing extra and wrong is added.
A12: Score (1-5) | B12: Average of the three criteria, calculated automatically.
A13: Consistency | B13: Run the same prompt 3 times: High = same quality each time, Medium = minor differences, Low = quality changes a lot. Blank = not tested.

Sheet Summary
A1: Summary
A3: Setup item | B3: Your entry
A4: v1 run: model | B4: Gemini 3.5 Flash-Lite, paid tier (self-reported by Gemini)
A5: v2 run: model | B5: Gemini 3.8 Flash (self-reported by Gemini)
A6: v3 run: model | B6: Gemini 3.1 Pro, paid tier (self-reported by Gemini)
A7: Interface | B7: Gemini web app (confirm). Earlier notes said Google AI Studio.
A8: Temperature | B8: Default. The Gemini app does not let you set it.
A9: Date tested | B9: Update with your real dates
A10: System instructions | B10: None
A11: Warning: the three runs report three different models. A model's self-description is not fully reliable, so check the model picker for each saved chat. If they really differ, the v1 to v3 gains are partly due to the model (v3 on a Pro model), not only the prompt. Say this in your reflection, or rerun v1 and v2 on the same model as v3.
A13: Results per task (automatic)
A14: Task ID | B14: Category | C14: v1 | D14: v2 | E14: v3 | F14: Improvement (v3 minus v1) | G14: Best version
A15: R1 | B15: Reasoning | C15: =IF(COUNTIFS('Evaluation Log'!$A$2:$A$34,$A15,'Evaluation Log'!$D$2:$D$34,C$14,'Evaluation Log'!$M$2:$M$34,">0")=0,"",SUMIFS('Evaluation Log'!$M$2:$M$34,'Evaluation Log'!$A$2:$A$34,$A15,'Evaluation Log'!$D$2:$D$34,C$14)) -> 4.7 | D15: =IF(COUNTIFS('Evaluation Log'!$A$2:$A$34,$A15,'Evaluation Log'!$D$2:$D$34,D$14,'Evaluation Log'!$M$2:$M$34,">0")=0,"",SUMIFS('Evaluation Log'!$M$2:$M$34,'Evaluation Log'!$A$2:$A$34,$A15,'Evaluation Log'!$D$2:$D$34,D$14)) -> 5 | E15: =IF(COUNTIFS('Evaluation Log'!$A$2:$A$34,$A15,'Evaluation Log'!$D$2:$D$34,E$14,'Evaluation Log'!$M$2:$M$34,">0")=0,"",SUMIFS('Evaluation Log'!$M$2:$M$34,'Evaluation Log'!$A$2:$A$34,$A15,'Evaluation Log'!$D$2:$D$34,E$14)) -> 5 | F15: =IF(AND(ISNUMBER(C15),ISNUMBER(E15)),E15-C15,"") -> 0.3 | G15: =IF(COUNT(C15:E15)<3,"",IF(MAX(C15:E15)=MIN(C15:E15),"All equal",INDEX($C$14:$E$14,MATCH(MAX(C15:E15),C15:E15,0)))) -> v2
A16: R2 | B16: Reasoning | C16: =IF(COUNTIFS('Evaluation Log'!$A$2:$A$34,$A16,'Evaluation Log'!$D$2:$D$34,C$14,'Evaluation Log'!$M$2:$M$34,">0")=0,"",SUMIFS('Evaluation Log'!$M$2:$M$34,'Evaluation Log'!$A$2:$A$34,$A16,'Evaluation Log'!$D$2:$D$34,C$14)) -> 4.3 | D16: =IF(COUNTIFS('Evaluation Log'!$A$2:$A$34,$A16,'Evaluation Log'!$D$2:$D$34,D$14,'Evaluation Log'!$M$2:$M$34,">0")=0,"",SUMIFS('Evaluation Log'!$M$2:$M$34,'Evaluation Log'!$A$2:$A$34,$A16,'Evaluation Log'!$D$2:$D$34,D$14)) -> 5 | E16: =IF(COUNTIFS('Evaluation Log'!$A$2:$A$34,$A16,'Evaluation Log'!$D$2:$D$34,E$14,'Evaluation Log'!$M$2:$M$34,">0")=0,"",SUMIFS('Evaluation Log'!$M$2:$M$34,'Evaluation Log'!$A$2:$A$34,$A16,'Evaluation Log'!$D$2:$D$34,E$14)) -> 5 | F16: =IF(AND(ISNUMBER(C16),ISNUMBER(E16)),E16-C16,"") -> 0.7 | G16: =IF(COUNT(C16:E16)<3,"",IF(MAX(C16:E16)=MIN(C16:E16),"All equal",INDEX($C$14:$E$14,MATCH(MAX(C16:E16),C16:E16,0)))) -> v2
A17: R3 | B17: Reasoning | C17: =IF(COUNTIFS('Evaluation Log'!$A$2:$A$34,$A17,'Evaluation Log'!$D$2:$D$34,C$14,'Evaluation Log'!$M$2:$M$34,">0")=0,"",SUMIFS('Evaluation Log'!$M$2:$M$34,'Evaluation Log'!$A$2:$A$34,$A17,'Evaluation Log'!$D$2:$D$34,C$14)) -> 3.7 | D17: =IF(COUNTIFS('Evaluation Log'!$A$2:$A$34,$A17,'Evaluation Log'!$D$2:$D$34,D$14,'Evaluation Log'!$M$2:$M$34,">0")=0,"",SUMIFS('Evaluation Log'!$M$2:$M$34,'Evaluation Log'!$A$2:$A$34,$A17,'Evaluation Log'!$D$2:$D$34,D$14)) -> 4.7 | E17: =IF(COUNTIFS('Evaluation Log'!$A$2:$A$34,$A17,'Evaluation Log'!$D$2:$D$34,E$14,'Evaluation Log'!$M$2:$M$34,">0")=0,"",SUMIFS('Evaluation Log'!$M$2:$M$34,'Evaluation Log'!$A$2:$A$34,$A17,'Evaluation Log'!$D$2:$D$34,E$14)) -> 5 | F17: =IF(AND(ISNUMBER(C17),ISNUMBER(E17)),E17-C17,"") -> 1.3 | G17: =IF(COUNT(C17:E17)<3,"",IF(MAX(C17:E17)=MIN(C17:E17),"All equal",INDEX($C$14:$E$14,MATCH(MAX(C17:E17),C17:E17,0)))) -> v3
A18: E1 | B18: Extraction | C18: =IF(COUNTIFS('Evaluation Log'!$A$2:$A$34,$A18,'Evaluation Log'!$D$2:$D$34,C$14,'Evaluation Log'!$M$2:$M$34,">0")=0,"",SUMIFS('Evaluation Log'!$M$2:$M$34,'Evaluation Log'!$A$2:$A$34,$A18,'Evaluation Log'!$D$2:$D$34,C$14)) -> 4.3 | D18: =IF(COUNTIFS('Evaluation Log'!$A$2:$A$34,$A18,'Evaluation Log'!$D$2:$D$34,D$14,'Evaluation Log'!$M$2:$M$34,">0")=0,"",SUMIFS('Evaluation Log'!$M$2:$M$34,'Evaluation Log'!$A$2:$A$34,$A18,'Evaluation Log'!$D$2:$D$34,D$14)) -> 4.7 | E18: =IF(COUNTIFS('Evaluation Log'!$A$2:$A$34,$A18,'Evaluation Log'!$D$2:$D$34,E$14,'Evaluation Log'!$M$2:$M$34,">0")=0,"",SUMIFS('Evaluation Log'!$M$2:$M$34,'Evaluation Log'!$A$2:$A$34,$A18,'Evaluation Log'!$D$2:$D$34,E$14)) -> 5 | F18: =IF(AND(ISNUMBER(C18),ISNUMBER(E18)),E18-C18,"") -> 0.7 | G18: =IF(COUNT(C18:E18)<3,"",IF(MAX(C18:E18)=MIN(C18:E18),"All equal",INDEX($C$14:$E$14,MATCH(MAX(C18:E18),C18:E18,0)))) -> v3
A19: E2 | B19: Extraction | C19: =IF(COUNTIFS('Evaluation Log'!$A$2:$A$34,$A19,'Evaluation Log'!$D$2:$D$34,C$14,'Evaluation Log'!$M$2:$M$34,">0")=0,"",SUMIFS('Evaluation Log'!$M$2:$M$34,'Evaluation Log'!$A$2:$A$34,$A19,'Evaluation Log'!$D$2:$D$34,C$14)) -> 4.3 | D19: =IF(COUNTIFS('Evaluation Log'!$A$2:$A$34,$A19,'Evaluation Log'!$D$2:$D$34,D$14,'Evaluation Log'!$M$2:$M$34,">0")=0,"",SUMIFS('Evaluation Log'!$M$2:$M$34,'Evaluation Log'!$A$2:$A$34,$A19,'Evaluation Log'!$D$2:$D$34,D$14)) -> 4.7 | E19: =IF(COUNTIFS('Evaluation Log'!$A$2:$A$34,$A19,'Evaluation Log'!$D$2:$D$34,E$14,'Evaluation Log'!$M$2:$M$34,">0")=0,"",SUMIFS('Evaluation Log'!$M$2:$M$34,'Evaluation Log'!$A$2:$A$34,$A19,'Evaluation Log'!$D$2:$D$34,E$14)) -> 5 | F19: =IF(AND(ISNUMBER(C19),ISNUMBER(E19)),E19-C19,"") -> 0.7 | G19: =IF(COUNT(C19:E19)<3,"",IF(MAX(C19:E19)=MIN(C19:E19),"All equal",INDEX($C$14:$E$14,MATCH(MAX(C19:E19),C19:E19,0)))) -> v3
A20: E3 | B20: Extraction | C20: =IF(COUNTIFS('Evaluation Log'!$A$2:$A$34,$A20,'Evaluation Log'!$D$2:$D$34,C$14,'Evaluation Log'!$M$2:$M$34,">0")=0,"",SUMIFS('Evaluation Log'!$M$2:$M$34,'Evaluation Log'!$A$2:$A$34,$A20,'Evaluation Log'!$D$2:$D$34,C$14)) -> 3.7 | D20: =IF(COUNTIFS('Evaluation Log'!$A$2:$A$34,$A20,'Evaluation Log'!$D$2:$D$34,D$14,'Evaluation Log'!$M$2:$M$34,">0")=0,"",SUMIFS('Evaluation Log'!$M$2:$M$34,'Evaluation Log'!$A$2:$A$34,$A20,'Evaluation Log'!$D$2:$D$34,D$14)) -> 5 | E20: =IF(COUNTIFS('Evaluation Log'!$A$2:$A$34,$A20,'Evaluation Log'!$D$2:$D$34,E$14,'Evaluation Log'!$M$2:$M$34,">0")=0,"",SUMIFS('Evaluation Log'!$M$2:$M$34,'Evaluation Log'!$A$2:$A$34,$A20,'Evaluation Log'!$D$2:$D$34,E$14)) -> 5 | F20: =IF(AND(ISNUMBER(C20),ISNUMBER(E20)),E20-C20,"") -> 1.3 | G20: =IF(COUNT(C20:E20)<3,"",IF(MAX(C20:E20)=MIN(C20:E20),"All equal",INDEX($C$14:$E$14,MATCH(MAX(C20:E20),C20:E20,0)))) -> v2
A21: S1 | B21: Summarization | C21: =IF(COUNTIFS('Evaluation Log'!$A$2:$A$34,$A21,'Evaluation Log'!$D$2:$D$34,C$14,'Evaluation Log'!$M$2:$M$34,">0")=0,"",SUMIFS('Evaluation Log'!$M$2:$M$34,'Evaluation Log'!$A$2:$A$34,$A21,'Evaluation Log'!$D$2:$D$34,C$14)) | D21: =IF(COUNTIFS('Evaluation Log'!$A$2:$A$34,$A21,'Evaluation Log'!$D$2:$D$34,D$14,'Evaluation Log'!$M$2:$M$34,">0")=0,"",SUMIFS('Evaluation Log'!$M$2:$M$34,'Evaluation Log'!$A$2:$A$34,$A21,'Evaluation Log'!$D$2:$D$34,D$14)) | E21: =IF(COUNTIFS('Evaluation Log'!$A$2:$A$34,$A21,'Evaluation Log'!$D$2:$D$34,E$14,'Evaluation Log'!$M$2:$M$34,">0")=0,"",SUMIFS('Evaluation Log'!$M$2:$M$34,'Evaluation Log'!$A$2:$A$34,$A21,'Evaluation Log'!$D$2:$D$34,E$14)) | F21: =IF(AND(ISNUMBER(C21),ISNUMBER(E21)),E21-C21,"") | G21: =IF(COUNT(C21:E21)<3,"",IF(MAX(C21:E21)=MIN(C21:E21),"All equal",INDEX($C$14:$E$14,MATCH(MAX(C21:E21),C21:E21,0))))
